Workbook
Name \a: #N/A
Name \b: #N/A
Name \c: #N/A
Name \d: #N/A
Name \e: #N/A
Name \f: #N/A
Name \g: #N/A
Name \h: #N/A
Name \i: #N/A
Name \j: #N/A
Name \k: #N/A
Name \m: #N/A
Name \n: #N/A
Name \t: #N/A
Name _____A1: #REF!
Name _____a14: #REF!
Name _____a23: #REF!
Name _____b1: #REF!
Name _____B5: #REF!
Name _____bod1: #REF!
Name _____bod2: #REF!
Name _____bod3: #REF!
Name _____bod4: #REF!
Name _____bri2: #REF!
Name _____bri3: #REF!
Name _____c: #REF!
Name _____c1: #REF!
Name _____c2: #REF!
Name _____d1: #REF!
Name _____d108: #REF!
Name _____d2: #REF!
Name _____d3: #REF!
Name _____DR1: #REF!
Name _____DR2: #REF!
Name _____E1: #REF!
Name _____E2: #REF!
Name _____Ext13: #REF!
Name _____Ext14: #REF!
Name _____Ext19: #REF!
Name _____Ext22: #REF!
Name _____Ext23: #REF!
Name _____Ext27: #REF!
Name _____Ext28: #REF!
Name _____Ext29: #REF!
Name _____Ext3: #REF!
Name _____Ext31: #REF!
Name _____Ext32: #REF!
Name _____Ext33: #REF!
Name _____Ext34: #REF!
Name _____Ext38: #REF!
Name _____Ext40: #REF!
Name _____Ext45: #REF!
Name _____Ext46: #REF!
Name _____Ext47: #REF!
Name _____Ext48: #REF!
Name _____Ext49: #REF!
Name _____Ext50: #REF!
Name _____Ext51: #REF!
Name _____Ext55: #REF!
Name _____Ext56: #REF!

Sheet Payment Claim
B2: Payment Claim
B4: Progress Certificate No. | D4: PC004
B5: Payment Period | D5: 06/12/25 - 31/01/25
B6: Contractor Representative | D6: Gavin Law
B7: Contractor Name | D7: Rirratjingu Enterprises Pty Ltd (ACN 56 639 548 137)
B8: PO No. | D8: 3106883069
B9: SAP WBS | D9: Z-2264070.04.50.30.01
B10: Contract No. | D10: PH-AA-0001
B11: Contract Title | D11: PLANT HIRE SERVICES FOR BENTHIC REMOVAL
D12: AUD
B13: Claim Value | D13: =Payment_Summary!V19 -> 0
B14: Amount Approved for Payment | D14: =Payment_Summary!AC19 -> 174764.75 | H14: =D14-D13 -> 174764.75
B16: AUSTRALIAN DOLLAR
B17: 1 | C17: CONTRACT PRICE (excl. GST) | F17: =Payment_Summary!G19 -> 2316587.2
B18: 2 | C18: AUTHORISED VARIATIONS | F18: =F19-F17 -> 599324.9
B19: 3 | C19: REVISED CONTRACT PRICE | F19: =Payment_Summary!S19 -> 2915912.1
B20: 4 | C20: APPROVED TO DATE | F20: =SUBTOTAL(9,F21:F29) -> 1329178.5 | H20: =TRUE() -> TRUE
C21: PC001 Sep-25 | F21: 41059.03
C22: PC002 Oct-25 | F22: 652005.36
C23: PC003 Nov-25 - 6 Dec-25 | F23: 461349.34
C24: PC004 Dec 25 - Jan 26 | F24: =D14 -> 174764.75
B30: 5 | C30: REMAINING VALUE | F30: =F19-F20 -> 1586733.6
B32: In accordance with General Condition cl 14.2(c), the Company Representative responds with reasons for withholding payment as follows:
B33: - Refer to comments included at Attachment A
B35: Company Notes:
B36: Pump charges have been removed from this Progress Claim. WM will review with RAC which pumps are on site and charges can be captured in PC004.
B38: Attachments:
B39: 1 - PC003
B41: Approval | D41: Name | E41: Signature | F41: Date
B42: Procurement and Contracts | D42: Jake Shaw
B43: Project Controls | D43: Tong Fu
B44: Project Controls | D44: Alfredo Vitangcol
B45: Project Manager | D45: Shaine Sayed
B47: Attachment A - PC003

Sheet Payment_Summary
B1: PAYMENT CLAIM
B3: Contract Ref: | C3: ='Payment Claim'!D10 -> PH-AA-0001
B4: Contract Title: | C4: ='Payment Claim'!D11 -> PLANT HIRE SERVICES FOR BENTHIC REMOVAL
B5: Contractor: | C5: ='Payment Claim'!D7 -> Rirratjingu Enterprises Pty Ltd (ACN 56 639 548 137)
B6: SAP WBS: | C6: ='Payment Claim'!D9 -> Z-2264070.04.50.30.01
B7: Payment No: | C7: ='Payment Claim'!D4 -> PC004
B8: Payment Period: | C8: ='Payment Claim'!D5 -> 06/12/25 - 31/01/25
U9: SUBMITTED BY CONTRACTOR | AB9: ASSESSED BY COMPANY | AI9: DELTA THIS CLAIM
F10: Awarded Contract Price | H10: Contract Variation 001 | J10: Contract Variation 002 | L10: Contract Variation 003 | N10: Contract Variation 004 | P10: Contract Variation 00 | R10: Revised Contract Price | U10: This Claim | W10: Previously Certified Amounts | Y10: Cumulative to Date | AB10: This Claim | AD10: Previously Certified Amounts | AF10: Cumulative to Date
B11: ITEM | C11: DESCRIPTION | D11: LS/CP/ SOR/PS | E11: UNIT | F11: Hours | G11: Amount (AUD) | H11: Hours | I11: Amount (AUD) | J11: Hours | K11: Amount (AUD) | L11: Hours | M11: Amount (AUD) | N11: Hours | O11: Amount (AUD) | P11: Hours | Q11: Amount (AUD) | R11: Hours | S11: Amount (AUD) | U11: QTY | V11: AMOUNT (A) | W11: QTY | X11: AMOUNT (B) | Y11: QTY | Z11: AMOUNT (C = A + B) | AB11: QTY | AC11: AMOUNT (D) | AD11: QTY | AE11: AMOUNT (E) | AF11: QTY | AG11: AMOUNT (F = D + E) | AI11: QTY | AJ11: AMOUNT (G = F - C)
B12: A.2 | C12: Schedule of Rates | G12: =SUBTOTAL(9,G13:G16) -> 2316587.2 | S12: =SUBTOTAL(9,S13:S16) -> 2867960.1
B13: A.2.1 | C13: Rates for Mobilisation & Demobilisation - Manual Personnel | D13: SOR | E13: Lot | F13: 222 | G13: 35451.9 | H13: =547-222 -> 325 | I13: =82014.8-G13 -> 46562.9 | R13: =+F13+H13+J13+L13+N13 -> 547 | S13: =+G13+I13+K13+M13+O13 -> 82014.8 | U13: =Y13-W13 -> 0 | V13: =Z13-X13 -> 0 | W13: 81 | X13: 25349.85 | Y13: 81 | Z13: 25349.85 | AB13: =AF13-AD13 -> 0 | AC13: =AG13-AE13 -> 0 | AD13: ='A.2.1_Mob&Demob Personnel'!I59 -> 81 | AE13: ='A.2.1_Mob&Demob Personnel'!M59 -> 25349.85 | AF13: ='A.2.1_Mob&Demob Personnel'!J59 -> 81 | AG13: ='A.2.1_Mob&Demob Personnel'!N59 -> 25349.85 | AI13: =AB13-U13 -> 0 | AJ13: =AC13-V13 -> 0
B14: A.2.3 | C14: Rates for Labour | D14: SOR | E14: Hours | F14: 6048 | G14: 698544 | H14: =9603-F14 -> 3555 | I14: =1203354-G14 -> 504810 | R14: =+F14+H14+J14+L14+N14 -> 9603 | S14: =+G14+I14+K14+M14+O14 -> 1203354 | U14: =Y14-W14 -> 0 | V14: =Z14-X14 -> 0 | W14: 3400.5 | X14: 396110 | Y14: 3400.5 | Z14: 396110 | AB14: =AF14-AD14 -> 1470 | AC14: =AG14-AE14 -> 174753.75 | AD14: ='A.2.3 Labour Costs'!BN20 -> 3135 | AE14: ='A.2.3 Labour Costs'!BR20 -> 365444.75 | AF14: ='A.2.3 Labour Costs'!BO20 -> 4605 | AG14: ='A.2.3 Labour Costs'!BS20 -> 540198.5 | AI14: =AB14-U14 -> 1470 | AJ14: =AC14-V14 -> 174753.75
B15: A.2.4 | C15: Rates for Mobilisation & Demobilisation - Plant & Equipment | D15: SOR | E15: Lot | F15: 0 | G15: 412206.65 | H15: 0 | I15: 0 | R15: =+F15+H15+J15+L15+N15 -> 0 | S15: =+G15+I15+K15+M15+O15 -> 412206.65 | U15: =Y15-W15 -> 0 | V15: =Z15-X15 -> 0 | W15: 9 | X15: 348397.3 | Y15: 9 | Z15: 348397.3 | AB15: =AF15-AD15 -> 0 | AC15: =AG15-AE15 -> 0 | AD15: ='A.2.4_Mob&Demob PE'!I36 -> 9 | AE15: ='A.2.4_Mob&Demob PE'!M36 -> 348397.3 | AF15: ='A.2.4_Mob&Demob PE'!J36 -> 9 | AG15: ='A.2.4_Mob&Demob PE'!N36 -> 348397.3 | AI15: =AB15-U15 -> 0 | AJ15: =AC15-V15 -> 0
B16: A.2.5 | C16: Rates for Plant & Equipment | D16: SOR | E16: Days | F16: 0 | G16: 1170384.6 | H16: 0 | I16: 0 | R16: =+F16+H16+J16+L16+N16 -> 0 | S16: =+G16+I16+K16+M16+O16 -> 1170384.6 | U16: =Y16-W16 -> 0 | V16: =Z16-X16 -> 0 | W16: 3779.5 | X16: 354159.63 | Y16: 3779.5 | Z16: 354159.63 | AB16: =AF16-AD16 -> 9.1 | AC16: =AG16-AE16 -> 11 | AD16: ='A.2.5 PE'!AU41 -> 100.7 | AE16: ='A.2.5 PE'!AY41 -> 83 | AF16: ='A.2.5 PE'!AV41 -> 109.8 | AG16: ='A.2.5 PE'!AZ41 -> 94 | AI16: =AB16-U16 -> 9.1 | AJ16: =AC16-V16 -> 11
B17: A.4 | C17: Variations
B18: A.4.1 | C18: Variations - Site Instruction | D18: CP | E18: Lot | H18: 0 | I18: 47952 | R18: =+F18+H18+J18+L18+N18 -> 0 | S18: =+G18+I18+K18+M18+O18 -> 47952 | U18: =Y18-W18 -> 0 | V18: =Z18-X18 -> 0 | W18: 0 | X18: 30396.95 | Y18: 0 | Z18: 30396.95 | AB18: 0 | AC18: =AG18-AE18 -> 0 | AD18: =AF18-AB18 -> 0 | AE18: =A.4_Purchase!J24-A.4_Purchase!J22 -> 30396.95 | AF18: 0 | AG18: =A.4_Purchase!J24 -> 30396.95 | AI18: 0 | AJ18: =AC18-V18 -> 0
C19: Total | F19: =SUBTOTAL(9,F12:F16) -> 6270 | G19: =SUBTOTAL(9,G12:G18) -> 2316587.2 | I19: =SUBTOTAL(9,I12:I18) -> 599324.9 | K19: =SUBTOTAL(9,K12:K18) -> 0 | M19: =SUBTOTAL(9,M12:M18) -> 0 | O19: =SUBTOTAL(9,O12:O18) -> 0 | Q19: =SUBTOTAL(9,Q12:Q18) -> 0 | R19: =SUBTOTAL(9,R12:R18) -> 10150 | S19: =SUBTOTAL(9,S12:S18) -> 2915912.1 | U19: =SUBTOTAL(9,U12:U18) -> 0 | V19: =SUBTOTAL(9,V12:V18) -> 0 | W19: =SUBTOTAL(9,W12:W18) -> 7270 | X19: =SUBTOTAL(9,X12:X18) -> 1154413.7 | Y19: =SUBTOTAL(9,Y12:Y18) -> 7270 | Z19: =SUBTOTAL(9,Z12:Z18) -> 1154413.7 | AB19: =SUBTOTAL(9,AB12:AB18) -> 1479.1 | AC19: =SUBTOTAL(9,AC12:AC18) -> 174764.75 | AD19: =SUBTOTAL(9,AD12:AD18) -> 3325.7 | AE19: =SUBTOTAL(9,AE12:AE18) -> 769671.85 | AF19: =SUBTOTAL(9,AF12:AF18) -> 4804.8 | AG19: =SUBTOTAL(9,AG12:AG18) -> 944436.6 | AI19: =SUBTOTAL(9,AI12:AI18) -> 1479.1 | AJ19: =SUBTOTAL(9,AJ12:AJ18) -> 174764.75

Sheet A.2.1_Mob&Demob Personnel
B1: Contract Ref: | C1: =Payment_Summary!C3 -> PH-AA-0001
B2: Contract Title: | C2: =Payment_Summary!C4 -> PLANT HIRE SERVICES FOR BENTHIC REMOVAL
B3: Contractor: | C3: =Payment_Summary!C5 -> Rirratjingu Enterprises Pty Ltd (ACN 56 639 548 137)
B4: SAP WBS: | C4: =Payment_Summary!C6 -> Z-2264070.04.50.30.01
B5: Payment No: | C5: =Payment_Summary!C7 -> PC004
B6: Payment Period: | C6: =Payment_Summary!C8 -> 06/12/25 - 31/01/25
B8: TABLE A.2.1 - Mobilisation / Demobilistation - Personnel
P9: Hours (Previous Payments) | AA9: Payments (AUD) (Previous Payments)
B10: Item | C10: Position | D10: Personnel Name(s) | E10: Labour Rate AUD/Hr | F10: UoM | H10: This Payment | I10: Previous Payments Hours | J10: Total Payment Hours | L10: This Payment AUD | M10: Previous Payments AUD | N10: Total Payment AUD | P10: PC001 | Q10: PC002 | R10: PC003 | S10: PC004 | T10: PC005 | U10: PC006 | V10: PC007 | W10: PC008 | X10: PC009 | Y10: PC010 | AA10: =P10 -> PC001 | AB10: =Q10 -> PC002 | AC10: =R10 -> PC003 | AD10: =S10 -> PC004 | AE10: =T10 -> PC005 | AF10: =U10 -> PC006 | AG10: =V10 -> PC007 | AH10: =W10 -> PC008 | ... AJ10: =Y10 -> PC010 | AK10: Contractor Comments | AL10: Company Comments
C11: Mobilisation - Personnel
B12: A.2.1-101a | C12: Operators - pre-mobilisation medical | D12: Byron McCann | E12: 115.5 | F12: Hrs | I12: =SUM(P12:Y12) -> 4 | J12: =H12+I12 -> 4 | L12: =H12*E12 -> 0 | M12: =SUM(AA12:AJ12) -> 462 | N12: =+L12+M12 -> 462 | P12: 4 | AA12: 462 | AL12: 4hrs as per Schedule A.99
B13: A.2.1-101a | C13: Operators - pre-mobilisation medical | D13: Steven Mungatopi | E13: 115.5 | F13: Hrs | I13: =SUM(P13:Y13) -> 4 | J13: =H13+I13 -> 4 | L13: =H13*E13 -> 0 | M13: =SUM(AA13:AJ13) -> 462 | N13: =+L13+M13 -> 462 | P13: 4 | AA13: 462
B14: A.2.1-101a | C14: Operators - pre-mobilisation medical | D14: Arthur De Saint Andrieu | E14: 115.5 | F14: Hrs | I14: =SUM(P14:Y14) -> 4 | J14: =H14+I14 -> 4 | L14: =H14*E14 -> 0 | M14: =SUM(AA14:AJ14) -> 462 | N14: =+L14+M14 -> 462 | P14: 4 | AA14: 462
B15: A.2.1-101a | C15: Operators - pre-mobilisation medical | D15: Andres Ramirez | E15: 115.5 | F15: Hrs | I15: =SUM(P15:Y15) -> 4 | J15: =H15+I15 -> 4 | L15: =H15*E15 -> 0 | M15: =SUM(AA15:AJ15) -> 462 | N15: =+L15+M15 -> 462 | P15: 4 | AA15: 462
B16: A.2.1-101a | C16: Operators - pre-mobilisation medical | D16: Jack Barlee | E16: 115.5 | F16: Hrs | I16: =SUM(P16:Y16) -> 4 | J16: =H16+I16 -> 4 | L16: =H16*E16 -> 0 | M16: =SUM(AA16:AJ16) -> 462 | N16: =+L16+M16 -> 462 | P16: 4 | AA16: 462
B17: A.2.1-101a | C17: Operators - pre-mobilisation medical | D17: Stewart Rioli | E17: 115.5 | F17: Hrs | I17: =SUM(P17:Y17) -> 4 | J17: =H17+I17 -> 4 | L17: =H17*E17 -> 0 | M17: =SUM(AA17:AJ17) -> 462 | N17: =+L17+M17 -> 462 | Q17: 4 | AA17: 0 | AB17: 462
B18: A.2.1-101a | C18: Operators - pre-mobilisation medical | D18: Joy Mather | E18: 115.5 | F18: Hrs | I18: =SUM(P18:Y18) -> 4 | J18: =H18+I18 -> 4 | L18: =H18*E18 -> 0 | M18: =SUM(AA18:AJ18) -> 462 | N18: =+L18+M18 -> 462 | Q18: 4 | AA18: 0 | AB18: 462
B19: A.2.1-101a | C19: Operators - pre-mobilisation medical | D19: Payden Coghill | E19: 115.5 | F19: Hrs | I19: =SUM(P19:Y19) -> 4 | J19: =H19+I19 -> 4 | L19: =H19*E19 -> 0 | M19: =SUM(AA19:AJ19) -> 462 | N19: =+L19+M19 -> 462 | Q19: 4 | AA19: 0 | AB19: 462
B20: A.2.1-101a | C20: Operators - pre-mobilisation medical | D20: Jarrad Ernst | E20: 142 | F20: Hrs | I20: =SUM(P20:Y20) -> 4 | J20: =H20+I20 -> 4 | L20: =H20*E20 -> 0 | M20: =SUM(AA20:AJ20) -> 568 | N20: =+L20+M20 -> 568 | R20: 4 | AC20: 568
C22: Subtotal - pre-mobilisation medical | H22: =SUBTOTAL(9,H12:H21) -> 0 | I22: =SUBTOTAL(9,I12:I21) -> 36 | J22: =SUBTOTAL(9,J12:J21) -> 36 | L22: =SUBTOTAL(9,L12:L21) -> 0 | M22: =SUBTOTAL(9,M12:M21) -> 4264 | N22: =SUBTOTAL(9,N12:N21) -> 4264 | P22: =SUBTOTAL(9,P12:P21) -> 20 | Q22: =SUBTOTAL(9,Q12:Q21) -> 12 | R22: =SUBTOTAL(9,R12:R21) -> 4 | S22: =SUBTOTAL(9,S12:S21) -> 0 | T22: =SUBTOTAL(9,T12:T21) -> 0 | U22: =SUBTOTAL(9,U12:U21) -> 0 | V22: =SUBTOTAL(9,V12:V21) -> 0 | W22: =SUBTOTAL(9,W12:W21) -> 0 | ... Y22: =SUBTOTAL(9,Y12:Y21) -> 0
C23: Mobilisation - preparation & onboarding
B24: A.2.1-101b | C24: Operators - preparation & onboarding | D24: Byron McCann | E24: 1750.65 | F24: EA | I24: =SUM(P24:Y24) -> 1 | J24: =H24+I24 -> 1 | L24: =H24*E24 -> 0 | M24: =SUM(AA24:AJ24) -> 1750.65 | N24: =+L24+M24 -> 1750.65 | P24: 1 | AA24: 1750.65 | AL24: incl's site-specific PPE, (2hrs + 3hrs) for offsite / onsite inductions as per Schedule A.99
B25: A.2.1-101b | C25: Operators - preparation & onboarding | D25: Steven Mungatopi | E25: 1750.65 | F25: EA | I25: =SUM(P25:Y25) -> 1 | J25: =H25+I25 -> 1 | L25: =H25*E25 -> 0 | M25: =SUM(AA25:AJ25) -> 1750.65 | N25: =+L25+M25 -> 1750.65 | P25: 1 | AA25: 1750.65
B26: A.2.1-101b | C26: Operators - preparation & onboarding | D26: Arthur De Saint Andrieu | E26: 1750.65 | F26: EA | I26: =SUM(P26:Y26) -> 1 | J26: =H26+I26 -> 1 | L26: =H26*E26 -> 0 | M26: =SUM(AA26:AJ26) -> 1750.65 | N26: =+L26+M26 -> 1750.65 | P26: 1 | AA26: 1750.65
B27: A.2.1-101b | C27: Operators - preparation & onboarding | D27: Andres Ramirez | E27: 1750.65 | F27: EA | I27: =SUM(P27:Y27) -> 1 | J27: =H27+I27 -> 1 | L27: =H27*E27 -> 0 | M27: =SUM(AA27:AJ27) -> 1750.65 | N27: =+L27+M27 -> 1750.65 | P27: 1 | AA27: 1750.65
B28: A.2.1-101b | C28: Operators - preparation & onboarding | D28: Jack Barlee | E28: 1750.65 | F28: EA | I28: =SUM(P28:Y28) -> 1 | J28: =H28+I28 -> 1 | L28: =H28*E28 -> 0 | M28: =SUM(AA28:AJ28) -> 1750.65 | N28: =+L28+M28 -> 1750.65 | P28: 1 | AA28: 1750.65
B29: A.2.1-101b | C29: Operators - preparation & onboarding | D29: Stewart Rioli | E29: 1750.65 | F29: EA | I29: =SUM(P29:Y29) -> 1 | J29: =H29+I29 -> 1 | L29: =H29*E29 -> 0 | M29: =SUM(AA29:AJ29) -> 1750.65 | N29: =+L29+M29 -> 1750.65 | Q29: 1 | AA29: 0 | AB29: 1750.65
B30: A.2.1-101b | C30: Operators - preparation & onboarding | D30: Joy Mather | E30: 1750.65 | F30: EA | I30: =SUM(P30:Y30) -> 1 | J30: =H30+I30 -> 1 | L30: =H30*E30 -> 0 | M30: =SUM(AA30:AJ30) -> 1750.65 | N30: =+L30+M30 -> 1750.65 | Q30: 1 | AA30: 0 | AB30: 1750.65
B31: A.2.1-101b | C31: Operators - preparation & onboarding | D31: Payden Coghill | E31: 1750.65 | F31: EA | I31: =SUM(P31:Y31) -> 1 | J31: =H31+I31 -> 1 | L31: =H31*E31 -> 0 | M31: =SUM(AA31:AJ31) -> 1750.65 | N31: =+L31+M31 -> 1750.65 | Q31: 1 | AA31: 0 | AB31: 1750.65
B32: A.2.1-101b | C32: Operators - preparation & onboarding | D32: Jarrad Ernst | E32: 1750.65 | F32: EA | I32: =SUM(P32:Y32) -> 1 | J32: =H32+I32 -> 1 | L32: =H32*E32 -> 0 | M32: =SUM(AA32:AJ32) -> 1750.65 | N32: =+L32+M32 -> 1750.65 | R32: 1 | AC32: 1750.65
C34: Subtotal - preparation & onboarding | H34: =SUBTOTAL(9,H24:H33) -> 0 | I34: =SUBTOTAL(9,I24:I33) -> 9 | J34: =SUBTOTAL(9,J24:J33) -> 9 | L34: =SUBTOTAL(9,L24:L33) -> 0 | M34: =SUBTOTAL(9,M24:M33) -> 15755.85 | N34: =SUBTOTAL(9,N24:N33) -> 15755.85 | P34: =SUBTOTAL(9,P24:P33) -> 5 | Q34: =SUBTOTAL(9,Q24:Q33) -> 3 | R34: =SUBTOTAL(9,R24:R33) -> 1 | S34: =SUBTOTAL(9,S24:S33) -> 0 | T34: =SUBTOTAL(9,T24:T33) -> 0 | U34: =SUBTOTAL(9,U24:U33) -> 0 | V34: =SUBTOTAL(9,V24:V33) -> 0 | W34: =SUBTOTAL(9,W24:W33) -> 0 | ... Y34: =SUBTOTAL(9,Y24:Y33) -> 0
C35: Mobilisation - mobilise to site
B36: A.2.1-101c | C36: Operators - mobilise to site | D36: Byron McCann | E36: 115.5 | F36: Hrs | I36: =SUM(P36:Y36) -> 5 | J36: =H36+I36 -> 5 | L36: =H36*E36 -> 0 | M36: =SUM(AA36:AJ36) -> 577.5 | N36: =+L36+M36 -> 577.5 | P36: 5 | AA36: 577.5 | AL36: 5hrs travel time as per Schedule A.99
B37: A.2.1-101c | C37: Operators - mobilise to site | D37: Steven Mungatopi | E37: 115.5 | F37: Hrs | I37: =SUM(P37:Y37) -> 5 | J37: =H37+I37 -> 5 | L37: =H37*E37 -> 0 | M37: =SUM(AA37:AJ37) -> 577.5 | N37: =+L37+M37 -> 577.5 | P37: 5 | AA37: 577.5
B38: A.2.1-101c | C38: Operators - mobilise to site | D38: Arthur De Saint Andrieu | E38: 115.5 | F38: Hrs | I38: =SUM(P38:Y38) -> 5 | J38: =H38+I38 -> 5 | L38: =H38*E38 -> 0 | M38: =SUM(AA38:AJ38) -> 577.5 | N38: =+L38+M38 -> 577.5 | P38: 5 | AA38: 577.5
B39: A.2.1-101c | C39: Operators - mobilise to site | D39: Andres Ramirez | E39: 115.5 | F39: Hrs | I39: =SUM(P39:Y39) -> 5 | J39: =H39+I39 -> 5 | L39: =H39*E39 -> 0 | M39: =SUM(AA39:AJ39) -> 577.5 | N39: =+L39+M39 -> 577.5 | P39: 5 | AA39: 577.5
B40: A.2.1-101c | C40: Operators - mobilise to site | D40: Jack Barlee | E40: 115.5 | F40: Hrs | I40: =SUM(P40:Y40) -> 5 | J40: =H40+I40 -> 5 | L40: =H40*E40 -> 0 | M40: =SUM(AA40:AJ40) -> 577.5 | N40: =+L40+M40 -> 577.5 | P40: 5 | AA40: 577.5
B41: A.2.1-101c | C41: Operators - mobilise to site | D41: Stewart Rioli | E41: 115.5 | F41: Hrs | I41: =SUM(P41:Y41) -> 5 | J41: =H41+I41 -> 5 | L41: =H41*E41 -> 0 | M41: =SUM(AA41:AJ41) -> 577.5 | N41: =+L41+M41 -> 577.5 | Q41: 5 | AB41: 577.5
B42: A.2.1-101c | C42: Operators - mobilise to site | D42: Joy Mather | E42: 115.5 | F42: Hrs | I42: =SUM(P42:Y42) -> 5 | J42: =H42+I42 -> 5 | L42: =H42*E42 -> 0 | M42: =SUM(AA42:AJ42) -> 577.5 | N42: =+L42+M42 -> 577.5 | Q42: 5 | AB42: 577.5
B43: A.2.1-101c | C43: Operators - mobilise to site | D43: Payden Coghill | E43: 115.5 | F43: Hrs | I43: =SUM(P43:Y43) -> 5 | J43: =H43+I43 -> 5 | L43: =H43*E43 -> 0 | M43: =SUM(AA43:AJ43) -> 577.5 | N43: =+L43+M43 -> 577.5 | Q43: 5 | AB43: 577.5
...

Sheet A.2.3 Labour Costs
B1: Contract Ref: | C1: =Payment_Summary!C3 -> PH-AA-0001
B2: Contract Title: | C2: =Payment_Summary!C4 -> PLANT HIRE SERVICES FOR BENTHIC REMOVAL
B3: Contractor: | C3: =Payment_Summary!C5 -> Rirratjingu Enterprises Pty Ltd (ACN 56 639 548 137)
B4: SAP WBS: | C4: =Payment_Summary!C6 -> Z-2264070.04.50.30.01
B5: Payment No: | C5: =Payment_Summary!C7 -> PC004
B6: Payment Period: | C6: =Payment_Summary!C8 -> 06/12/25 - 31/01/25
B8: Table A.2.3 - Costs for Personnel
B10: Item | C10: Position | D10: Personnel Name(s) | E10: Labour Rate AUD/Hr | G10: 45997 | H10: =G10+1 -> 45998 | I10: =H10+1 -> 45999 | J10: =I10+1 -> 46000 | K10: =J10+1 -> 46001 | L10: =K10+1 -> 46002 | M10: =L10+1 -> 46003 | N10: =M10+1 -> 46004 | O10: =N10+1 -> 46005 | ... BK10: =BJ10+1 -> 46053 | BM10: This Payment Hours | BN10: Previous Payments Hours | BO10: Total Payment Hours | BQ10: This Payment AUD | BR10: Previous Payments AUD | BS10: Total Payment AUD | BU10: PC001 | BV10: PC002 | BW10: PC003 | BX10: PC004 | BY10: PC005 | BZ10: PC006 | CA10: PC007 | CB10: PC008 | CC10: PC009 | CD10: PC010 | CF10: =BU10 -> PC001 | CG10: =BV10 -> PC002 | CH10: =BW10 -> PC003 | CI10: =BX10 -> PC004 | CJ10: =BY10 -> PC005 | CK10: =BZ10 -> PC006 | CL10: =CA10 -> PC007 | CM10: =CB10 -> PC008 | ... CO10: =CD10 -> PC010 | CQ10: Contractor Comments | CR10: Company Comments
CR11: See comments in individual cells
B12: A.2.3-101 | C12: Operators | D12: Byron McCann | E12: 115.5 | H12: 10 | I12: 10 | J12: 10 | K12: 11.5 | L12: 11.5 | M12: 11.5 | N12: 11.5 | O12: 10 | AK12: 10 | AL12: 11.5 | AM12: 11.5 | AN12: 11.5 | AO12: 10 | AP12: 10 | AQ12: 11.5 | AR12: 11.5 | AS12: 11.5 | AT12: 11.5 | AU12: 11.5 | AV12: 11.5 | AW12: 11.5 | AX12: 10 | BM12: =SUM(G12:BL12) -> 241 | BN12: =SUM(BU12:CD12) -> 587 | BO12: =BM12+BN12 -> 828 | BQ12: =E12*BM12 -> 27835.5 | BR12: =SUM(CF12:CO12) -> 67798.5 | BS12: =+BQ12+BR12 -> 95634 | BU12: 16 | BV12: 269.5 | BW12: 301.5 | CF12: =BU12*E12 -> 1848 | CG12: 31127.25 | CH12: 34823.25
B13: A.2.3-101 | C13: Operators | D13: Steven Mungatopi | E13: 115.5 | H13: 10 | I13: 10 | J13: 10 | K13: 11.5 | L13: 11.5 | M13: 11.5 | O13: 10 | AK13: 10 | AL13: 11.5 | AM13: 11.5 | AN13: 11.5 | AO13: 10 | AP13: 10 | AQ13: 11.5 | AR13: 11.5 | AS13: 11.5 | AT13: 11.5 | AU13: 11.5 | AV13: 11.5 | AW13: 11.5 | AX13: 10 | BM13: =SUM(G13:BL13) -> 229.5 | BN13: =SUM(BU13:CD13) -> 535.5 | BO13: =BM13+BN13 -> 765 | BQ13: =E13*BM13 -> 26507.25 | BR13: =SUM(CF13:CO13) -> 61850.25 | BS13: =+BQ13+BR13 -> 88357.5 | BU13: 16 | BV13: 228 | BW13: 291.5 | CF13: =BU13*E13 -> 1848 | CG13: 26334 | CH13: 33668.25
B14: A.2.3-101 | C14: Operators | D14: Arthur De Saint Andrieu | E14: 115.5 | H14: 0 | I14: 0 | K14: 11.5 | L14: 11.5 | M14: 11.5 | N14: 11.5 | O14: 10 | AK14: 10 | AL14: 11.5 | AM14: 11.5 | AN14: 11.5 | AO14: 10 | AP14: 10 | AQ14: 11.5 | AR14: 11.5 | AS14: 11.5 | AT14: 11.5 | AU14: 11.5 | AV14: 11.5 | AW14: 11.5 | AX14: 10 | BM14: =SUM(G14:BL14) -> 211 | BN14: =SUM(BU14:CD14) -> 587 | BO14: =BM14+BN14 -> 798 | BQ14: =E14*BM14 -> 24370.5 | BR14: =SUM(CF14:CO14) -> 67798.5 | BS14: =+BQ14+BR14 -> 92169 | BU14: 16 | BV14: 269.5 | BW14: 301.5 | CF14: =BU14*E14 -> 1848 | CG14: 31127.25 | CH14: 34823.25
B15: A.2.3-101 | C15: Operators | D15: Jack Barlee | E15: 115.5 | H15: 10 | I15: 10 | J15: 10 | K15: 11.5 | L15: 11.5 | M15: 11.5 | N15: 11.5 | O15: 10 | AK15: 10 | AL15: 11.5 | AM15: 11.5 | AN15: 11.5 | AO15: 10 | AP15: 10 | AQ15: 11.5 | AR15: 11.5 | AS15: 11.5 | AT15: 11.5 | AU15: 11.5 | AV15: 11.5 | AW15: 11.5 | BM15: =SUM(G15:BL15) -> 231 | BN15: =SUM(BU15:CD15) -> 587 | BO15: =BM15+BN15 -> 818 | BQ15: =E15*BM15 -> 26680.5 | BR15: =SUM(CF15:CO15) -> 67798.5 | BS15: =+BQ15+BR15 -> 94479 | BU15: 16 | BV15: 269.5 | BW15: 301.5 | CF15: =BU15*E15 -> 1848 | CG15: 31127.25 | CH15: 34823.25
B16: A.2.3-101 | C16: Operators | D16: Stewart Rioli | E16: 115.5 | H16: 10 | I16: 10 | J16: 10 | K16: 11.5 | L16: 11.5 | M16: 11.5 | N16: 11.5 | O16: 10 | AR16: 10 | AS16: 11.5 | AT16: 11.5 | AU16: 11.5 | AV16: 11.5 | AW16: 11.5 | AX16: 10 | BM16: =SUM(G16:BL16) -> 163.5 | BN16: =SUM(BU16:CD16) -> 505.5 | BO16: =BM16+BN16 -> 669 | BQ16: =E16*BM16 -> 18884.25 | BR16: =SUM(CF16:CO16) -> 58385.25 | BS16: =+BQ16+BR16 -> 77269.5 | BV16: 204 | BW16: 301.5 | CG16: 23562 | CH16: 34823.25
A17: 10 | B17: A.2.3-101 | C17: Operators | D17: Payden Coghill | E17: 115.5 | H17: 10 | I17: 10 | J17: 10 | K17: 11.5 | L17: 11.5 | M17: 11.5 | N17: 11.5 | O17: 10 | AN17: 10 | AO17: 10 | AP17: 10 | AQ17: 11.5 | AR17: 11.5 | AS17: 11.5 | AT17: 11.5 | AU17: 11.5 | AV17: 11.5 | AW17: 11.5 | AX17: 10 | BM17: =SUM(G17:BL17) -> 206.5 | BN17: =SUM(BU17:CD17) -> 206.5 | BO17: =BM17+BN17 -> 413 | BQ17: =E17*BM17 -> 23850.75 | BR17: =SUM(CF17:CO17) -> 23850.75 | BS17: =+BQ17+BR17 -> 47701.5 | BV17: 0 | BW17: 206.5 | CG17: 0 | CH17: 23850.75
B18: A.2.3-101 | C18: Operators | D18: Jarrad Ernst | E18: 142 | H18: 11.5 | I18: 11.5 | J18: 11.5 | K18: 11.5 | L18: 11.5 | M18: 11.5 | N18: 11.5 | O18: 10 | AK18: 10 | AL18: 11.5 | AM18: 11.5 | AN18: 11.5 | AO18: 11.5 | AP18: 11.5 | AQ18: 11.5 | AR18: 11.5 | AS18: 6.5 | BM18: =SUM(G18:BL18) -> 187.5 | BN18: =SUM(BU18:CD18) -> 126.5 | BO18: =BM18+BN18 -> 314 | BQ18: =E18*BM18 -> 26625 | BR18: =SUM(CF18:CO18) -> 17963 | BS18: =+BQ18+BR18 -> 44588 | BV18: 0 | BW18: 126.5 | CG18: 0 | CH18: 17963
D20: TOTAL | G20: =SUBTOTAL(9,G12:G19) -> 0 | H20: =SUBTOTAL(9,H12:H19) -> 61.5 | I20: =SUBTOTAL(9,I12:I19) -> 61.5 | J20: =SUBTOTAL(9,J12:J19) -> 61.5 | K20: =SUBTOTAL(9,K12:K19) -> 80.5 | L20: =SUBTOTAL(9,L12:L19) -> 80.5 | M20: =SUBTOTAL(9,M12:M19) -> 80.5 | N20: =SUBTOTAL(9,N12:N19) -> 69 | ... AN20: =SUBTOTAL(9,AN12:AN19) -> 67.5 | AX20: =SUBTOTAL(9,AX12:AX19) -> 50 | BK20: =SUBTOTAL(9,BK12:BK19) -> 0 | BM20: =SUBTOTAL(9,BM12:BM19) -> 1470 | BN20: =SUBTOTAL(9,BN12:BN19) -> 3135 | BO20: =SUBTOTAL(9,BO12:BO19) -> 4605 | BQ20: =SUBTOTAL(9,BQ12:BQ19) -> 174753.75 | BR20: =SUBTOTAL(9,BR12:BR19) -> 365444.75 | BS20: =SUBTOTAL(9,BS12:BS19) -> 540198.5 | BU20: =SUBTOTAL(9,BU12:BU19) -> 64 | BV20: =SUBTOTAL(9,BV12:BV19) -> 1240.5 | BW20: =SUBTOTAL(9,BW12:BW19) -> 1830.5 | BX20: =SUBTOTAL(9,BX12:BX19) -> 0 | BY20: =SUBTOTAL(9,BY12:BY19) -> 0 | BZ20: =SUBTOTAL(9,BZ12:BZ19) -> 0 | CA20: =SUBTOTAL(9,CA12:CA19) -> 0 | CB20: =SUBTOTAL(9,CB12:CB19) -> 0 | ... CD20: =SUBTOTAL(9,CD12:CD19) -> 0 | CF20: =SUBTOTAL(9,CF12:CF19) -> 7392 | CG20: =SUBTOTAL(9,CG12:CG19) -> 143277.75 | CH20: =SUBTOTAL(9,CH12:CH19) -> 214775 | CI20: =SUBTOTAL(9,CI12:CI19) -> 0 | CJ20: =SUBTOTAL(9,CJ12:CJ19) -> 0 | CK20: =SUBTOTAL(9,CK12:CK19) -> 0 | CL20: =SUBTOTAL(9,CL12:CL19) -> 0 | CM20: =SUBTOTAL(9,CM12:CM19) -> 0 | ... CO20: =SUBTOTAL(9,CO12:CO19) -> 0

Sheet A.2.4_Mob&Demob PE
B1: Contract Ref: | C1: =Payment_Summary!C3 -> PH-AA-0001
B2: Contract Title: | C2: =Payment_Summary!C4 -> PLANT HIRE SERVICES FOR BENTHIC REMOVAL
B3: Contractor: | C3: =Payment_Summary!C5 -> Rirratjingu Enterprises Pty Ltd (ACN 56 639 548 137)
B4: SAP WBS: | C4: =Payment_Summary!C6 -> Z-2264070.04.50.30.01
B5: Payment No: | C5: =Payment_Summary!C7 -> PC004
B6: Payment Period: | C6: =Payment_Summary!C8 -> 06/12/25 - 31/01/25
B8: Table A.2.4 - Mobilisation & Demobilisation - Plant & Equipment
P9: Hours (Previous Payments) | AA9: Payments (AUD) (Previous Payments)
B10: Item | C10: Equipment Type | D10: Equipment No. | E10: Rate (AUD) | F10: UoM | H10: This Payment | I10: Previous Payments Hours | J10: Total Payment Hours | L10: This Payment AUD | M10: Previous Payments AUD | N10: Total Payment AUD | P10: PC001 | Q10: PC002 | R10: PC003 | S10: PC004 | T10: PC005 | U10: PC006 | V10: PC007 | W10: PC008 | X10: PC009 | Y10: PC010 | AA10: =P10 -> PC001 | AB10: =Q10 -> PC002 | AC10: =R10 -> PC003 | AD10: =S10 -> PC004 | AE10: =T10 -> PC005 | AF10: =U10 -> PC006 | AG10: =V10 -> PC007 | AH10: =W10 -> PC008 | ... AJ10: =Y10 -> PC010 | AK10: Contractor Comments | AL10: Company Comments
C11: Mobilisation - Plant and Equipment (by road)
B12: A.7.4-101 | C12: 25t Excavator LGP Tracks | D12: EX10 | E12: 71393.85 | F12: Lot | I12: =SUM(P12:Y12) -> 1 | J12: =H12+I12 -> 1 | L12: =H12*E12 -> 0 | M12: =SUM(AA12:AJ12) -> 71393.85 | N12: =+L12+M12 -> 71393.85 | Q12: 1 | AB12: 71393.85
B13: A.7.4-102 | C13: 36t Excavator LGP Tracks | D13: EX17 | E13: 78376.65 | F13: Lot | I13: =SUM(P13:Y13) -> 1 | J13: =H13+I13 -> 1 | L13: =H13*E13 -> 0 | M13: =SUM(AA13:AJ13) -> 78376.65 | N13: =+L13+M13 -> 78376.65 | Q13: 1 | AB13: 78376.65
B14: A.7.4-103 | C14: D6 Dozer LGP Tracks | D14: YQ087 | E14: 47512.3 | F14: Lot | I14: =SUM(P14:Y14) -> 1 | J14: =H14+I14 -> 1 | L14: =H14*E14 -> 0 | M14: =SUM(AA14:AJ14) -> 47512.3 | N14: =+L14+M14 -> 47512.3 | Q14: 1 | AB14: 47512.3
B15: A.7.4-104a | C15: 30t Articulated Dumptruck #1 | D15: TAT52 | E15: 33811.8 | F15: Lot | I15: =SUM(P15:Y15) -> 1 | J15: =H15+I15 -> 1 | L15: =H15*E15 -> 0 | M15: =SUM(AA15:AJ15) -> 33811.8 | N15: =+L15+M15 -> 33811.8 | Q15: 1 | AB15: 33811.8
B16: A.7.4-104b | C16: 30t Articulated Dumptruck #2 | D16: TAT56 | E16: 33811.8 | F16: Lot | I16: =SUM(P16:Y16) -> 1 | J16: =H16+I16 -> 1 | L16: =H16*E16 -> 0 | M16: =SUM(AA16:AJ16) -> 33811.8 | N16: =+L16+M16 -> 33811.8 | Q16: 1 | AB16: 33811.8
B17: A.7.4-105 | C17: Service Truck | D17: IGROUP58 | E17: 35967.25 | F17: Lot | I17: =SUM(P17:Y17) -> 1 | J17: =H17+I17 -> 1 | L17: =H17*E17 -> 0 | M17: =SUM(AA17:AJ17) -> 35967.25 | N17: =+L17+M17 -> 35967.25 | Q17: 1 | AB17: 35967.25
B18: A.7.4-106 | C18: Rigid Watercart | D18: TW06 | E18: 27874.55 | F18: Lot | I18: =SUM(P18:Y18) -> 1 | J18: =H18+I18 -> 1 | L18: =H18*E18 -> 0 | M18: =SUM(AA18:AJ18) -> 27874.55 | N18: =+L18+M18 -> 27874.55 | Q18: 1 | AB18: 27874.55
B19: A.7.4-107a | C19: 4WD Twin Cab LV #1 | D19: CC21IT | E19: 9824.55 | F19: Lot | I19: =SUM(P19:Y19) -> 1 | J19: =H19+I19 -> 1 | L19: =H19*E19 -> 0 | M19: =SUM(AA19:AJ19) -> 9824.55 | N19: =+L19+M19 -> 9824.55 | Q19: 1 | AB19: 9824.55
B20: A.7.4-107b | C20: 4WD Twin Cab LV #2 | D20: CC95AY | E20: 9824.55 | F20: Lot | I20: =SUM(P20:Y20) -> 1 | J20: =H20+I20 -> 1 | L20: =H20*E20 -> 0 | M20: =SUM(AA20:AJ20) -> 9824.55 | N20: =+L20+M20 -> 9824.55 | Q20: 1 | AB20: 9824.55
C22: Subtotal - Plant and Equipment (by road) | H22: =SUBTOTAL(9,H12:H21) -> 0 | I22: =SUBTOTAL(9,I12:I21) -> 9 | J22: =SUBTOTAL(9,J12:J21) -> 9 | L22: =SUBTOTAL(9,L12:L21) -> 0 | M22: =SUBTOTAL(9,M12:M21) -> 348397.3 | N22: =SUBTOTAL(9,N12:N21) -> 348397.3 | P22: =SUBTOTAL(9,P12:P21) -> 0 | Q22: =SUBTOTAL(9,Q12:Q21) -> 9 | R22: =SUBTOTAL(9,R12:R21) -> 0 | S22: =SUBTOTAL(9,S12:S21) -> 0 | T22: =SUBTOTAL(9,T12:T21) -> 0 | U22: =SUBTOTAL(9,U12:U21) -> 0 | V22: =SUBTOTAL(9,V12:V21) -> 0 | W22: =SUBTOTAL(9,W12:W21) -> 0 | ... Y22: =SUBTOTAL(9,Y12:Y21) -> 0 | AA22: =SUBTOTAL(9,AA12:AA21) -> 0 | AB22: =SUBTOTAL(9,AB12:AB21) -> 348397.3 | AC22: =SUBTOTAL(9,AC12:AC21) -> 0 | AD22: =SUBTOTAL(9,AD12:AD21) -> 0 | AE22: =SUBTOTAL(9,AE12:AE21) -> 0 | AF22: =SUBTOTAL(9,AF12:AF21) -> 0 | AG22: =SUBTOTAL(9,AG12:AG21) -> 0 | AH22: =SUBTOTAL(9,AH12:AH21) -> 0 | ... AJ22: =SUBTOTAL(9,AJ12:AJ21) -> 0
C23: Demobilisation - Plant and Equipment (by barge)
B24: A.7.4-101 | C24: 25t Excavator LGP Tracks | E24: 6790.85 | F24: Lot | I24: =SUM(P24:Y24) -> 0 | J24: =H24+I24 -> 0 | L24: =H24*E24 -> 0 | M24: =SUM(AA24:AJ24) -> 0 | N24: =+L24+M24 -> 0
B25: A.7.4-102 | C25: 36t Excavator LGP Tracks | E25: 8044.85 | F25: Lot | I25: =SUM(P25:Y25) -> 0 | J25: =H25+I25 -> 0 | L25: =H25*E25 -> 0 | M25: =SUM(AA25:AJ25) -> 0 | N25: =+L25+M25 -> 0
B26: A.7.4-103 | C26: D6 Dozer LGP Tracks | E26: 13294.6 | F26: Lot | I26: =SUM(P26:Y26) -> 0 | J26: =H26+I26 -> 0 | L26: =H26*E26 -> 0 | M26: =SUM(AA26:AJ26) -> 0 | N26: =+L26+M26 -> 0
B27: A.7.4-104a | C27: 30t Articulated Dumptruck #1 | E27: 10552.3 | F27: Lot | I27: =SUM(P27:Y27) -> 0 | J27: =H27+I27 -> 0 | L27: =H27*E27 -> 0 | M27: =SUM(AA27:AJ27) -> 0 | N27: =+L27+M27 -> 0
B28: A.7.4-104b | C28: 30t Articulated Dumptruck #2 | E28: 10552.3 | F28: Lot | I28: =SUM(P28:Y28) -> 0 | J28: =H28+I28 -> 0 | L28: =H28*E28 -> 0 | M28: =SUM(AA28:AJ28) -> 0 | N28: =+L28+M28 -> 0
B29: A.7.4-105 | C29: Service Truck | E29: 6386.05 | F29: Lot | I29: =SUM(P29:Y29) -> 0 | J29: =H29+I29 -> 0 | L29: =H29*E29 -> 0 | M29: =SUM(AA29:AJ29) -> 0 | N29: =+L29+M29 -> 0
B30: A.7.4-106 | C30: Rigid Watercart | E30: 4819.1 | F30: Lot | I30: =SUM(P30:Y30) -> 0 | J30: =H30+I30 -> 0 | L30: =H30*E30 -> 0 | M30: =SUM(AA30:AJ30) -> 0 | N30: =+L30+M30 -> 0
B31: A.7.4-107a | C31: 4WD Twin Cab LV #1 | E31: 1684.65 | F31: Lot | I31: =SUM(P31:Y31) -> 0 | J31: =H31+I31 -> 0 | L31: =H31*E31 -> 0 | M31: =SUM(AA31:AJ31) -> 0 | N31: =+L31+M31 -> 0
B32: A.7.4-107b | C32: 4WD Twin Cab LV #2 | E32: 1684.65 | F32: Lot
C34: Subtotal - Plant and Equipment (by barge) | H34: =SUBTOTAL(9,H24:H32) -> 0 | I34: =SUBTOTAL(9,I24:I32) -> 0 | J34: =SUBTOTAL(9,J24:J32) -> 0 | L34: =SUBTOTAL(9,L24:L32) -> 0 | M34: =SUBTOTAL(9,M24:M32) -> 0 | N34: =SUBTOTAL(9,N24:N32) -> 0 | P34: =SUBTOTAL(9,P24:P32) -> 0 | Q34: =SUBTOTAL(9,Q24:Q32) -> 0 | R34: =SUBTOTAL(9,R24:R32) -> 0 | S34: =SUBTOTAL(9,S24:S32) -> 0 | T34: =SUBTOTAL(9,T24:T32) -> 0 | U34: =SUBTOTAL(9,U24:U32) -> 0 | V34: =SUBTOTAL(9,V24:V32) -> 0 | W34: =SUBTOTAL(9,W24:W32) -> 0 | ... Y34: =SUBTOTAL(9,Y24:Y32) -> 0 | AA34: =SUBTOTAL(9,AA24:AA32) -> 0 | AB34: =SUBTOTAL(9,AB24:AB32) -> 0 | AC34: =SUBTOTAL(9,AC24:AC32) -> 0 | AD34: =SUBTOTAL(9,AD24:AD32) -> 0 | AE34: =SUBTOTAL(9,AE24:AE32) -> 0 | AF34: =SUBTOTAL(9,AF24:AF32) -> 0 | AG34: =SUBTOTAL(9,AG24:AG32) -> 0 | AH34: =SUBTOTAL(9,AH24:AH32) -> 0 | ... AJ34: =SUBTOTAL(9,AJ24:AJ32) -> 0
C36: Total - Mobilisation & Demobilisation - Plant & Equipment | H36: =SUBTOTAL(9,H11:H35)-H34 -> 0 | I36: =SUBTOTAL(9,I11:I35)-I34 -> 9 | J36: =SUBTOTAL(9,J11:J35)-J34 -> 9 | L36: =SUBTOTAL(9,L11:L35) -> 0 | M36: =SUBTOTAL(9,M11:M35) -> 348397.3 | N36: =SUBTOTAL(9,N11:N35) -> 348397.3 | P36: =SUBTOTAL(9,P11:P35)-P34 -> 0 | Q36: =SUBTOTAL(9,Q11:Q35)-Q34 -> 9 | R36: =SUBTOTAL(9,R11:R35)-R34 -> 0 | S36: =SUBTOTAL(9,S11:S35)-S34 -> 0 | T36: =SUBTOTAL(9,T11:T35)-T34 -> 0 | U36: =SUBTOTAL(9,U11:U35)-U34 -> 0 | V36: =SUBTOTAL(9,V11:V35)-V34 -> 0 | W36: =SUBTOTAL(9,W11:W35)-W34 -> 0 | ... Y36: =SUBTOTAL(9,Y11:Y35)-Y34 -> 0 | AA36: =SUBTOTAL(9,AA11:AA35) -> 0 | AB36: =SUBTOTAL(9,AB11:AB35) -> 348397.3 | AC36: =SUBTOTAL(9,AC11:AC35) -> 0 | AD36: =SUBTOTAL(9,AD11:AD35) -> 0 | AE36: =SUBTOTAL(9,AE11:AE35) -> 0 | AF36: =SUBTOTAL(9,AF11:AF35) -> 0 | AG36: =SUBTOTAL(9,AG11:AG35) -> 0 | AH36: =SUBTOTAL(9,AH11:AH35) -> 0 | ... AJ36: =SUBTOTAL(9,AJ11:AJ35) -> 0

Sheet A.2.5 PE
B1: Contract Ref: | C1: =Payment_Summary!C3 -> PH-AA-0001
B2: Contract Title: | C2: =Payment_Summary!C4 -> PLANT HIRE SERVICES FOR BENTHIC REMOVAL
B3: Contractor: | C3: =Payment_Summary!C5 -> Rirratjingu Enterprises Pty Ltd (ACN 56 639 548 137)
B4: SAP WBS: | C4: =Payment_Summary!C6 -> Z-2264070.04.50.30.01
B5: Payment No: | C5: =Payment_Summary!C7 -> PC004
B6: Payment Period: | C6: =Payment_Summary!C8 -> 06/12/25 - 31/01/25
B8: Table A.2.5 - Costs for Plant and Equipment
B10: Item | C10: Plant Classification | D10: Plant Equipment Reg. No | E10: PE Rate AUD/Day | F10: PE Rate AUD/Hr | H10: ='A.2.3 Labour Costs'!G10 -> 45997 | I10: ='A.2.3 Labour Costs'!H10 -> 45998 | J10: ='A.2.3 Labour Costs'!I10 -> 45999 | K10: ='A.2.3 Labour Costs'!J10 -> 46000 | L10: ='A.2.3 Labour Costs'!K10 -> 46001 | M10: ='A.2.3 Labour Costs'!L10 -> 46002 | N10: ='A.2.3 Labour Costs'!M10 -> 46003 | O10: ='A.2.3 Labour Costs'!N10 -> 46004 | ... AO10: ='A.2.3 Labour Costs'!AN10 -> 46030 | AP10: 46031 | AQ10: 46032 | AR10: 46033 | AS10: 46034 | AT10: 46035 | AU10: 46036 | AV10: 46037 | AW10: 46038 | AX10: 46039 | AY10: ='A.2.3 Labour Costs'!AX10 -> 46040 | AZ10: ='A.2.3 Labour Costs'!BK10 -> 46053 | BB10: Hours as per signed Dayworks | BC10: Combined monthly hours | BD10: Previous Payments Hours | BE10: Total Payment Hours | BG10: This Payment AUD | BH10: Previous Payments AUD | BI10: Total Payment AUD | BK10: PC001 | BL10: PC002 | BM10: PC003 | BN10: PC004 | BO10: PC005 | BP10: PC006 | BQ10: PC007 | BR10: PC008 | BS10: PC009 | BT10: PC010 | BV10: =BB10 -> Hours as per signed Dayworks | BW10: =BC10 -> Combined monthly hours | BX10: =BD10 -> Previous Payments Hours | BY10: =BE10 -> Total Payment Hours | BZ10: =BF10 -> 0 | CA10: =BG10 -> This Payment AUD | CB10: =BH10 -> Previous Payments AUD | CC10: =BI10 -> Total Payment AUD | ... CE10: =BK10 -> PC001 | CG10: Contractor Comments | CH10: Company Comments
B12: A.7.4-101 | C12: 25t Excavator LGP Tracks | D12: EX10 | E12: 1530.65 | F12: =E12/11 -> 139.15 | I12: 6 | J12: 4 | K12: 7 | L12: 6 | M12: 8 | N12: 8 | O12: 8 | AM12: 7 | AN12: 6 | AO12: 5 | AS12: 4 | AT12: 8 | AU12: 6 | AV12: 8 | AW12: 8 | AX12: 3 | AY12: 2 | BB12: =SUM(H12:AR12) -> 65 | BC12: =SUM(AS12:AS14) -> 11 | BD12: =SUM(BC12:BK12) -> #VALUE! | BE12: =AS12+AU12 -> 10 | BG12: =F12*AS12 -> 556.6 | BH12: =SUM(BM12:BV12) -> 148 | BI12: =+AX12+AY12 -> 5 | BL12: 88 | BM12: 148 | BW12: 12245.2 | BX12: 20594.2 | CH12: See comments in individual cells
C13: 25t Excavator LGP Tracks - Standby | E13: 919.6 | F13: =E13/11 -> 83.6 | I13: 4 | J13: 6 | K13: 3 | L13: 5 | M13: 3 | N13: 3 | O13: 3 | P13: 10 | AL13: 10 | AM13: 4 | AN13: 5 | AO13: 6 | AS13: 7 | AT13: 3 | AU13: 5 | AV13: 3 | AW13: 3 | AX13: 8 | AY13: 9 | BB13: =SUM(H13:AR13) -> 62 | BD13: =SUM(BC13:BK13) -> #VALUE! | BE13: =AS13+AU13 -> 12 | BG13: =F13*AS13 -> 585.2 | BH13: =SUM(BM13:BV13) -> 113.5 | BI13: =+AX13+AY13 -> 17 | BL13: 76 | BM13: 113.5 | BW13: 6353.6 | BX13: 9488.6
C14: 25t Excavator LGP Tracks - Breakdown | E14: 0 | F14: =E14/11 -> 0 | BB14: =SUM(H14:AR14) -> 0 | BD14: =SUM(BC14:BK14) -> #VALUE! | BE14: =AS14+AU14 -> 0 | BG14: =F14*AS14 -> 0 | BH14: =SUM(BM14:BV14) -> 29 | BI14: =+AX14+AY14 -> 0 | BM14: 29 | BX14: 0
B15: A.7.4-102 | C15: 36t Excavator LGP Tracks | D15: EX17 | E15: 1851.3 | F15: =E15/11 -> 168.3 | I15: 7 | J15: 5 | K15: 7 | L15: 8 | M15: 8 | N15: 8 | O15: 5 | AP15: 3 | AQ15: 5 | AR15: 7 | AS15: 3 | AT15: 6 | AU15: 8 | AV15: 5 | AW15: 5 | AX15: 3 | AY15: 2 | BB15: =SUM(H15:AR15) -> 63 | BC15: =SUM(AS15:AS17) -> 11 | BD15: =SUM(BC15:BK15) -> #VALUE! | BE15: =AS15+AU15 -> 11 | BG15: =F15*AS15 -> 504.9 | BH15: =SUM(BM15:BV15) -> 160 | BI15: =+AX15+AY15 -> 5 | BL15: 22 | BM15: 160 | BW15: 3702.6 | BX15: 26928
C16: 36t Excavator LGP Tracks - Standby | E16: 1113.2 | F16: =E16/11 -> 101.2 | I16: 3 | J16: 5 | K16: 3 | L16: 3 | M16: 3 | N16: 3 | O16: 6 | P16: 10 | AP16: 7 | AQ16: 5 | AR16: 4 | AS16: 8 | AT16: 5 | AU16: 3 | AV16: 6 | AW16: 6 | AX16: 8 | AY16: 9 | BB16: =SUM(H16:AR16) -> 52 | BD16: =SUM(BC16:BK16) -> #VALUE! | BE16: =AS16+AU16 -> 11 | BG16: =F16*AS16 -> 809.6 | BH16: =SUM(BM16:BV16) -> 130.5 | BI16: =+AX16+AY16 -> 17 | BL16: 25 | BM16: 130.5 | BW16: 2530 | BX16: 13206.6
C17: 36t Excavator LGP Tracks - Breakdown | E17: 0 | F17: =E17/11 -> 0 | BB17: =SUM(H17:AR17) -> 0 | BD17: =SUM(BC17:BK17) -> #VALUE! | BE17: =AS17+AU17 -> 0 | BG17: =F17*AS17 -> 0 | BH17: =SUM(BM17:BV17) -> 0 | BI17: =+AX17+AY17 -> 0 | BL17: 8 | BM17: 0 | BW17: 0 | BX17: 0
B18: A.7.4-103 | C18: D6 Dozer LGP Tracks | D18: YQ087 | E18: 2813.25 | F18: =E18/11 -> 255.75 | I18: 2.4 | J18: 3 | K18: 3 | L18: 8.1 | AR18: 5.3 | AS18: 4.1 | AT18: 5.9 | AU18: 1.7 | AV18: 7 | AW18: 1.6 | BB18: =SUM(H18:AR18) -> 21.8 | BC18: =SUM(AS18:AS19) -> 11 | BD18: =SUM(BC18:BK18) -> #VALUE! | BE18: =AS18+AU18 -> 5.8 | BG18: =F18*AS18 -> 1048.575 | BH18: =SUM(BM18:BV18) -> 107.6 | BI18: =+AX18+AY18 -> 0 | BL18: 52.3 | BM18: 107.6 | BW18: 13375.725 | BX18: 27518.7
C19: D6 Dozer LGP Tracks - Standby | E19: 1687.95 | F19: =E19/11 -> 153.45 | I19: 8.6 | J19: 7 | K19: 7 | L19: 2.9 | AQ19: 11 | AR19: 5.7 | AS19: 6.9 | AT19: 5.1 | AV19: 4 | AW19: 9.4 | BB19: =SUM(H19:AR19) -> 42.2 | BD19: =SUM(BC19:BK19) -> #VALUE! | BE19: =AS19+AU19 -> 6.9 | BG19: =F19*AS19 -> 1058.805 | BH19: =SUM(BM19:BV19) -> 182.9 | BI19: =+AX19+AY19 -> 0 | BL19: 112.7 | BM19: 182.9 | BW19: 17293.815 | BX19: 28066.005
B20: A.7.4-104a | C20: 30t Articulated Dumptruck #1 | D20: TAT52 | E20: 1972.3 | F20: =E20/11 -> 179.3 | J20: 0 | L20: 5.2 | M20: 7.3 | N20: 8.3 | O20: 4 | AO20: 2.3 | AP20: 4.3 | AQ20: 3.7 | AR20: 2.5 | AT20: 3.4 | AU20: 5.8 | AV20: 5.8 | AW20: 8 | AX20: 2.8 | AY20: 2.2 | BB20: =SUM(H20:AR20) -> 37.6 | BC20: =SUM(AS20:AS22) -> 11 | BD20: =SUM(BC20:BK20) -> #VALUE! | BE20: =AS20+AU20 -> 5.8 | BG20: =F20*AS20 -> 0 | BH20: =SUM(BM20:BV20) -> 148.9 | BI20: =+AX20+AY20 -> 5 | BL20: 65.6 | BM20: 148.9 | BW20: 11762.08 | BX20: 26697.77
C21: 30t Articulated Dumptruck #1 - Standby | E21: 1185.8 | F21: =E21/11 -> 107.8 | L21: 5.8 | M21: 3.7 | N21: 3.7 | O21: 7 | P21: 10 | AO21: 8.7 | AP21: 5.7 | AQ21: 6.3 | AR21: 8.5 | AT21: 7.6 | AU21: 5.2 | AV21: 5.2 | AW21: 3 | AX21: 8.2 | AY21: 8.8 | BB21: =SUM(H21:AR21) -> 59.4 | BD21: =SUM(BC21:BK21) -> #VALUE! | BE21: =AS21+AU21 -> 5.2 | BG21: =F21*AS21 -> 0 | BH21: =SUM(BM21:BV21) -> 71.9 | BI21: =+AX21+AY21 -> 17 | BL21: 88.4 | BM21: 71.9 | BW21: 9529.52 | BX21: 7750.82
C22: 30t Articulated Dumptruck #1 - Breakdown | E22: 0 | F22: =E22/11 -> 0 | I22: 10 | J22: 10 | K22: 10 | AS22: 11 | BB22: =SUM(H22:AR22) -> 30 | BD22: =SUM(BC22:BK22) -> #VALUE! | BE22: =AS22+AU22 -> 11 | BG22: =F22*AS22 -> 0 | BH22: =SUM(BM22:BV22) -> 69.7 | BI22: =+AX22+AY22 -> 0 | BL22: 11 | BM22: 69.7 | BW22: 0 | BX22: 0
B23: A.7.4-104b | C23: 30t Articulated Dumptruck #2 | D23: TAT56 | E23: 1972.3 | F23: =E23/11 -> 179.3 | L23: 6 | M23: 6 | N23: 7 | AO23: 3.5 | AP23: 5 | AQ23: 5 | AR23: 1 | AT23: 4 | AU23: 4 | AV23: 5.8 | AW23: 7.2 | AX23: 1.5 | BB23: =SUM(H23:AR23) -> 33.5 | BC23: =SUM(AS23:AS25) -> 11 | BD23: =SUM(BC23:BK23) -> #VALUE! | BE23: =AS23+AU23 -> 4 | BG23: =F23*AS23 -> 0 | BH23: =SUM(BM23:BV23) -> 3.3 | BI23: =+AX23+AY23 -> 1.5 | BL23: 22.5 | BM23: 3.3 | BW23: 4034.25 | BX23: 591.69
C24: 30t Articulated Dumptruck #2 - Standby | E24: 1185.8 | F24: =E24/11 -> 107.8 | L24: 5 | M24: 5 | N24: 4 | O24: 11 | P24: 10 | AL24: 10 | AM24: 11 | AN24: 11 | AO24: 6.5 | AP24: 5 | AQ24: 5 | AR24: 9 | AT24: 5 | AU24: 5 | AV24: 5 | AW24: 3.8 | AX24: 9.5 | AY24: 11 | BB24: =SUM(H24:AR24) -> 92.5 | BD24: =SUM(BC24:BK24) -> #VALUE! | BE24: =AS24+AU24 -> 5 | BG24: =F24*AS24 -> 0 | BH24: =SUM(BM24:BV24) -> 0 | BI24: =+AX24+AY24 -> 20.5 | BL24: 0 | BM24: 0 | BW24: 0 | BX24: 0
C25: 30t Articulated Dumptruck #2 - Breakdown | E25: 0 | F25: =E25/11 -> 0 | I25: 10 | J25: 10 | K25: 10 | AS25: 11 | AT25: 2 | AU25: 2 | BB25: =SUM(H25:AR25) -> 30 | BD25: =SUM(BC25:BK25) -> #VALUE! | BE25: =AS25+AU25 -> 13 | BG25: =F25*AS25 -> 0 | BH25: =SUM(BM25:BV25) -> 287.2 | BI25: =+AX25+AY25 -> 0 | BL25: 119.5 | BM25: 287.2 | BW25: 0 | BX25: 0
B26: A.7.4-105 | C26: Service Truck | D26: IGROUP58 | E26: 1911.8 | F26: =E26/11 -> 173.8 | I26: 3.5 | J26: 0 | K26: 0.4 | L26: 0.4 | M26: 0.5 | AM26: 6.1 | AN26: 5.4 | AO26: 1 | AP26: 1.8 | AQ26: 3 | AR26: 4.8 | AS26: 6.8 | AT26: 1 | AU26: 0.2 | AV26: 0.4 | AW26: 0.5 | BB26: =SUM(H26:AR26) -> 26.9 | BC26: =SUM(AS26:AS28) -> 11 | BD26: =SUM(BC26:BK26) -> #VALUE! | BE26: =AS26+AU26 -> 7 | BG26: =F26*AS26 -> 1181.84 | BH26: =SUM(BM26:BV26) -> 47.6 | BI26: =+AX26+AY26 -> 0 | BL26: 14 | BM26: 47.6 | BW26: 2433.2 | BX26: 8272.88
C27: Service Truck - Standby | E27: 1149.5 | F27: =E27/11 -> 104.5 | I27: 6.5 | J27: 10 | K27: 9.6 | L27: 10.6 | M27: 10.6 | N27: 11 | O27: 11 | P27: 10 | AL27: 10 | AM27: 4.9 | AN27: 5.6 | AO27: 10 | AP27: 8.2 | AQ27: 7 | AR27: 6.2 | AS27: 4.2 | AT27: 10 | AU27: 10.8 | AV27: 10.6 | AW27: 10.5 | AX27: 11 | AY27: 11 | BB27: =SUM(H27:AR27) -> 131.2 | BD27: =SUM(BC27:BK27) -> #VALUE! | BE27: =AS27+AU27 -> 15 | BG27: =F27*AS27 -> 438.9 | BH27: =SUM(BM27:BV27) -> 228.3 | BI27: =+AX27+AY27 -> 22 | BL27: 151 | BM27: 228.3 | BW27: 15779.5 | BX27: 23857.35
C28: Service Truck - Breakdown | E28: 0 | F28: =E28/11 -> 0 | BB28: =SUM(H28:AR28) -> 0 | BD28: =SUM(BC28:BK28) -> #VALUE! | BE28: =AS28+AU28 -> 0 | BG28: =F28*AS28 -> 0 | BH28: =SUM(BM28:BV28) -> 14.6 | BI28: =+AX28+AY28 -> 0 | BM28: 14.6 | BX28: 0
B29: A.7.4-106 | C29: Rigid Watercart | D29: TW06 | E29: 1240.25 | F29: =E29/11 -> 112.75 | K29: 2 | L29: 2 | M29: 5 | N29: 8 | O29: 8 | AO29: 5 | AR29: 1 | AU29: 3 | AV29: 8 | AX29: 2 | BB29: =SUM(H29:AR29) -> 31 | BC29: =SUM(AS29:AS31) -> 11 | BD29: =SUM(BC29:BK29) -> #VALUE! | BE29: =AS29+AU29 -> 3 | BG29: =F29*AS29 -> 0 | BH29: =SUM(BM29:BV29) -> 183 | BI29: =+AX29+AY29 -> 2 | BL29: 62 | BM29: 183 | BW29: 6990.5 | BX29: 20633.25
C30: Rigid Watercart - Standby | E30: 744.15 | F30: =E30/11 -> 67.65 | K30: 8 | L30: 9 | M30: 6 | N30: 3 | O30: 3 | P30: 10 | AL30: 10 | AM30: 11 | AN30: 11 | AO30: 6 | AP30: 10 | AQ30: 10 | AR30: 9 | AT30: 11 | AU30: 8 | AV30: 3 | AW30: 11 | AX30: 9 | AY30: 11 | BB30: =SUM(H30:AR30) -> 106 | BD30: =SUM(BC30:BK30) -> #VALUE! | BE30: =AS30+AU30 -> 8 | BG30: =F30*AS30 -> 0 | BH30: =SUM(BM30:BV30) -> 95.5 | BI30: =+AX30+AY30 -> 20 | BL30: 102 | BM30: 95.5 | BW30: 6900.3 | BX30: 6460.575
C31: Rigid Watercart - Breakdown | E31: 0 | F31: =E31/11 -> 0 | I31: 10 | J31: 10 | AS31: 11 | BB31: =SUM(H31:AR31) -> 20 | BD31: =SUM(BC31:BK31) -> #VALUE! | BE31: =AS31+AU31 -> 11 | BG31: =F31*AS31 -> 0 | BH31: =SUM(BM31:BV31) -> 12 | BI31: =+AX31+AY31 -> 0 | BM31: 12 | BX31: 0
B32: A.7.4-107a | C32: 4WD Twin Cab LV #1 | D32: CC21IT | E32: 320.65 | F32: =E32/11 -> 29.15 | I32: 11 | J32: 11 | K32: 11 | L32: 11 | M32: 11 | N32: 11 | O32: 11 | P32: 11 | AL32: 11 | AM32: 11 | AN32: 11 | AO32: 11 | AP32: 11 | AQ32: 11 | AR32: 11 | AS32: 11 | AT32: 11 | AU32: 11 | AV32: 11 | AW32: 11 | AX32: 11 | AY32: 11 | BB32: =SUM(H32:AR32) -> 165 | BC32: =SUM(AS32:AS33) -> 11 | BD32: =SUM(BC32:BK32) -> #VALUE! | BE32: =AS32+AU32 -> 22 | BG32: =F32*AS32 -> 320.65 | BH32: =SUM(BM32:BV32) -> 297 | BI32: =+AX32+AY32 -> 22 | BL32: 0 | BM32: 297 | BW32: 0 | BX32: 8657.55
C33: 4WD Twin Cab LV #1 - Standby | E33: 193.6 | F33: =E33/11 -> 17.6 | BB33: =SUM(H33:AR33) -> 0 | BD33: =SUM(BC33:BK33) -> #VALUE! | BE33: =AS33+AU33 -> 0 | BG33: =F33*AS33 -> 0 | BH33: =SUM(BM33:BV33) -> 0 | BI33: =+AX33+AY33 -> 0 | BL33: 0 | BM33: 0 | BW33: 0 | BX33: 0
B34: A.7.4-107b | C34: 4WD Twin Cab LV #2 | D34: CC95AY | E34: 320.65 | F34: =E34/11 -> 29.15 | I34: 11 | J34: 11 | K34: 11 | L34: 11 | M34: 11 | N34: 11 | O34: 11 | P34: 11 | AL34: 11 | AM34: 11 | AN34: 11 | AO34: 11 | AP34: 11 | AQ34: 11 | AR34: 11 | AS34: 11 | AT34: 11 | AU34: 11 | AV34: 11 | AW34: 11 | AX34: 11 | AY34: 11 | BB34: =SUM(H34:AR34) -> 165 | BC34: =SUM(AS34:AS35) -> 11 | BD34: =SUM(BC34:BK34) -> #VALUE! | BE34: =AS34+AU34 -> 22 | BG34: =F34*AS34 -> 320.65 | BH34: =SUM(BM34:BV34) -> 297 | BI34: =+AX34+AY34 -> 22 | BL34: 0 | BM34: 297 | BW34: 0 | BX34: 8657.55
C35: 4WD Twin Cab LV #2 - Standby | E35: 193.6 | F35: =E35/11 -> 17.6 | BB35: =SUM(H35:AR35) -> 0 | BD35: =SUM(BC35:BK35) -> #VALUE! | BE35: =AS35+AU35 -> 0 | BG35: =F35*AS35 -> 0 | BH35: =SUM(BM35:BV35) -> 0 | BI35: =+AX35+AY35 -> 0 | BL35: 0 | BM35: 0 | BW35: 0 | BX35: 0
B36: A.7.4-107b | C36: 4WD Twin Cab LV #3 | D36: TBA | E36: 320.65 | F36: =E36/11 -> 29.15 | I36: 11 | J36: 11 | K36: 11 | L36: 11 | M36: 11 | N36: 11 | O36: 11 | P36: 11 | AL36: 11 | AM36: 11 | AN36: 11 | AO36: 11 | AP36: 11 | AQ36: 11 | AR36: 11 | AS36: 11 | AT36: 11 | AU36: 11 | AV36: 11 | AW36: 11 | AX36: 11 | AY36: 11 | BB36: =SUM(H36:AR36) -> 165 | BC36: =SUM(AS36:AS37) -> 11 | BD36: =SUM(BC36:BK36) -> #VALUE! | BE36: =AS36+AU36 -> 22 | BG36: =F36*AS36 -> 320.65 | BH36: =SUM(BM36:BV36) -> 132 | BI36: =+AX36+AY36 -> 22 | BM36: 132 | BX36: 3847.8
C37: 4WD Twin Cab LV #3 - Standby | E37: 193.6 | F37: =E37/11 -> 17.6 | BB37: =SUM(H37:AR37) -> 0 | BD37: =SUM(BC37:BK37) -> #VALUE! | BE37: =AS37+AU37 -> 0 | BG37: =F37*AS37 -> 0 | BH37: =SUM(BM37:BV37) -> 0 | BI37: =+AX37+AY37 -> 0 | BM37: 0 | BX37: 0
D41: TOTAL | H41: =SUBTOTAL(9,H12:H40) -> 0 | I41: =SUBTOTAL(9,I12:I40) -> 104 | J41: =SUBTOTAL(9,J12:J40) -> 103 | K41: =SUBTOTAL(9,K12:K40) -> 103 | L41: =SUBTOTAL(9,L12:L40) -> 110 | M41: =SUBTOTAL(9,M12:M40) -> 99.1 | N41: =SUBTOTAL(9,N12:N40) -> 100 | O41: =SUBTOTAL(9,O12:O40) -> 99 | ... AX41: =SUBTOTAL(9,AX12:AX40) -> 99 | AY41: =SUBTOTAL(9,AP12:AP40) -> 83 | AZ41: =SUBTOTAL(9,AQ12:AQ40) -> 94 | BB41: =SUBTOTAL(9,AS12:AS40) -> 110 | BC41: =SUBTOTAL(9,AT12:AT40) -> 110 | BD41: =SUBTOTAL(9,AU12:AU40) -> 100.7 | BE41: =SUBTOTAL(9,AV12:AV40) -> 109.8 | BG41: =SUBTOTAL(9,AX12:AX40) -> 99 | BH41: =SUBTOTAL(9,AY12:AY40) -> 99 | BI41: =SUBTOTAL(9,AZ12:AZ40) -> 0 | BK41: =SUBTOTAL(9,BB12:BB40) -> 1399.1 | BL41: =SUBTOTAL(9,BC12:BC40) -> 110 | BM41: =SUBTOTAL(9,BD12:BD40) -> #VALUE! | BN41: =SUBTOTAL(9,BE12:BE40) -> 210.7 | BO41: =SUBTOTAL(9,BF12:BF40) -> 0 | BP41: =SUBTOTAL(9,BG12:BG40) -> 7146.37 | BQ41: =SUBTOTAL(9,BH12:BH40) -> 2759.5 | BR41: =SUBTOTAL(9,BI12:BI40) -> 198 | ... BT41: =SUBTOTAL(9,BK12:BK40) -> 0 | BV41: =SUBTOTAL(9,BM12:BM40) -> 2759.5 | BW41: =SUBTOTAL(9,BN12:BN40) -> 0 | BX41: =SUBTOTAL(9,BO12:BO40) -> 0 | BY41: =SUBTOTAL(9,BP12:BP40) -> 0 | BZ41: =SUBTOTAL(9,BQ12:BQ40) -> 0 | CA41: =SUBTOTAL(9,BR12:BR40) -> 0 | CB41: =SUBTOTAL(9,BS12:BS40) -> 0 | CC41: =SUBTOTAL(9,BT12:BT40) -> 0 | ... CE41: =SUBTOTAL(9,BV12:BV40) -> 0

Sheet A.4_Purchase
B1: Contract Ref: | C1: =Payment_Summary!C3 -> PH-AA-0001
B2: Contract Title: | C2: =Payment_Summary!C4 -> PLANT HIRE SERVICES FOR BENTHIC REMOVAL
B3: Contractor: | C3: =Payment_Summary!C5 -> Rirratjingu Enterprises Pty Ltd (ACN 56 639 548 137)
B4: SAP WBS: | C4: =Payment_Summary!C6 -> Z-2264070.04.50.30.01
B5: Payment No: | C5: =Payment_Summary!C7 -> PC004
B6: Payment Period: | C6: =Payment_Summary!C8 -> 06/12/25 - 31/01/25
B8: Table A.4 - Purchase
B10: Payment No | C10: Item No. | D10: Description | E10: Invoice Date | F10: Invoice No. | G10: Vendor Name | H10: Invoice Amount (AUD) Excl. GST | I10: Markup (12%) | J10: Total | L10: Contractor Comments | M10: Company Comments
B12: PC001 | C12: A.4 | D12: Site Instruction 001 - Signage | E12: Various | F12: Various | G12: Various | H12: 15953.82 | I12: =H12*0.12 -> 1914.4584 | J12: =H12+I12 -> 17868.278
B13: PC002 | C13: A.4 | D13: Site Instruction 002 Float moves | E13: 45968 | F13: Docket no. 41301 | G13: BCC | H13: 1800 | I13: =H13*0.12 -> 216 | J13: =H13+I13 -> 2016
B14: PC002 | C14: A.4 | D14: Wallaby Beach Accomodation | F14: 1787 | G14: East Arnhem Real Estate | H14: 7318.14 | I14: =H14*0.12 -> 878.1768 | J14: =H14+I14 -> 8196.3168
B15: PC003 | C15: A.4 | D15: Wallaby Beach Accomodation - Jarrad Ernst | E15: 45994 | F15: 2035 | G15: East Arnhem Real Estate | H15: 2068.17 | I15: =H15*0.12 -> 248.1804 | J15: =H15+I15 -> 2316.3504
B16: =C5 -> PC004 | C16: A.4
B17: =C5 -> PC004 | C17: A.4
B18: =C5 -> PC004 | C18: A.4
B19: =C5 -> PC004 | C19: A.4
D22: Subtotal for This Payment | G22: =C5 -> PC004 | H22: =SUMIF($B$11:$B$21,$G22,H$11:H$21) -> 0 | I22: =SUMIF($B$11:$B$21,$G22,I$11:I$21) -> 0 | J22: =SUMIF($B$11:$B$21,$G22,J$11:J$21) -> 0
H23: .
D24: Total - Cumulative | H24: =ROUND(SUBTOTAL(9,H11:H21),2) -> 27140.13 | I24: =ROUND(SUBTOTAL(9,I11:I21),2) -> 3256.82 | J24: =ROUND(SUBTOTAL(9,J11:J21),2) -> 30396.95

Sheet Monthly Claim (Client)
A1: Monthly Claim - Rio Tinto
A3: Month Start (enter first of month): | B3: 45962 | K3: Minimum hours per calendar month | L3: 200
A4: Month End (auto): | B4: 45997
A6: Equipment | B6: Operated Hours | C6: Standby Hours | D6: Total Hours | E6: Plant Rate | F6: Days Hired | G6: Variations Rate | H6: Operator Rate | I6: Standby Rate | J6: Operated ex GST | K6: Standby ex GST | L6: Prep & Onboard | M6: Mob Barge | N6: DeMob Barge | O6: Mob Road | P6: DeMob Road | Q6: Op Induction | R6: Op Mob | S6: Op DeMob | T6: Fixed ex GST | U6: Subtotal ex GST | V6: Top-up Hours to Min | W6: Operated Rate (/hr) | X6: Top-up ex GST | Y6: Adj total ex GST
A7: 25t Excavator LGP Tracks | B7: =SUMIFS('Daily Log'!$C:$C,'Daily Log'!$B:$B,A7,'Daily Log'!$A:$A,">="&$B$3,'Daily Log'!$A:$A,"<="&$B$4) -> 151 | C7: =SUMIFS('Daily Log'!$D:$D,'Daily Log'!$B:$B,A7,'Daily Log'!$A:$A,">="&$B$3,'Daily Log'!$A:$A,"<="&$B$4) -> 153 | D7: =B7+C7 -> 304 | E7: =IFERROR(_xlfn.XLOOKUP(A7,'RE Rates'!$A:$A,'RE Rates'!$B:$B,0),0) -> 139.15 | I7: =IFERROR(_xlfn.XLOOKUP(A7,'RE Rates'!$A:$A,'RE Rates'!$E:$E,0),0) -> 83.6 | J7: =N(B7)*(N(E7)) -> 21011.65 | K7: =N(C7)*N(I7) -> 12790.8 | L7: =SUMIFS('Daily Log'!$K:$K,'Daily Log'!$B:$B,A7,'Daily Log'!$A:$A,">="&$B$3,'Daily Log'!$A:$A,"<="&$B$4) -> 0 | M7: =SUMIFS('Daily Log'!$G:$G,'Daily Log'!$B:$B,A7,'Daily Log'!$A:$A,">="&$B$3,'Daily Log'!$A:$A,"<="&$B$4) -> 0 | N7: =SUMIFS('Daily Log'!$H:$H,'Daily Log'!$B:$B,A7,'Daily Log'!$A:$A,">="&$B$3,'Daily Log'!$A:$A,"<="&$B$4) -> 0 | O7: =SUMIFS('Daily Log'!$I:$I,'Daily Log'!$B:$B,A7,'Daily Log'!$A:$A,">="&$B$3,'Daily Log'!$A:$A,"<="&$B$4) -> 0 | P7: =SUMIFS('Daily Log'!$J:$J,'Daily Log'!$B:$B,A7,'Daily Log'!$A:$A,">="&$B$3,'Daily Log'!$A:$A,"<="&$B$4) -> 0 | Q7: =SUMIFS('Daily Log'!$L:$L,'Daily Log'!$B:$B,A7,'Daily Log'!$A:$A,">="&$B$3,'Daily Log'!$A:$A,"<="&$B$4) -> 0 | R7: =SUMIFS('Daily Log'!$M:$M,'Daily Log'!$B:$B,A7,'Daily Log'!$A:$A,">="&$B$3,'Daily Log'!$A:$A,"<="&$B$4) -> 0 | S7: =SUMIFS('Daily Log'!$N:$N,'Daily Log'!$B:$B,A7,'Daily Log'!$A:$A,">="&$B$3,'Daily Log'!$A:$A,"<="&$B$4) -> 0 | T7: =N(L7)*IFERROR(_xlfn.XLOOKUP(A7,'RE Rates'!$A:$A,'RE Rates'!$F:$F,0),0)+N(M7)*IFERROR(_xlfn.XLOOKUP(A7,'RE Rates'!$A:$A,'RE Rates'!$G:$G,0),0)+N(N7)*IFERROR(_xlfn.XLOOKUP(A7,'RE Rates'!$A:$A,'RE Rates'!$H:$H,0),0)+N(O7)*IFERROR(_xlfn.XLOOKUP(A7,'RE Rates'!$A:$A,'RE Rates'!$I:$I,0),0)+N(P7)*IFERROR(_xlfn.XLOOKUP(A7,'RE Rates'!$A:$A,'RE Rates'!$J:$J,0),0)+N(Q7)*IFERROR(_xlfn.XLOOKUP(A7,'RE Rates'!$A:$A,'RE Rates'!$K:$K,0),0)+N(R7)*IFERROR(_xlfn.XLOOKUP(A7,'RE Rates'!$A:$A,'RE Rates'!$L:$L,0),0)+N(S7)*IFERROR(_xlfn.XLOOKUP(A7,'RE Rates'!$A:$A,'RE Rates'!$M:$M,0),0) -> 0 | U7: =N(J7)+N(K7)+N(T7) -> 33802.45 | V7: =MAX($L$3 - ROUND(N(D7),2), 0) -> 0 | W7: =N(E7) + N(H7) -> 139.15 | X7: =N(V7) * N(W7) -> 0 | Y7: =N(U7) + N(X7) -> 33802.45
A8: 36t Excavator LGP Tracks | B8: =SUMIFS('Daily Log'!$C:$C,'Daily Log'!$B:$B,A8,'Daily Log'!$A:$A,">="&$B$3,'Daily Log'!$A:$A,"<="&$B$4) -> 163 | C8: =SUMIFS('Daily Log'!$D:$D,'Daily Log'!$B:$B,A8,'Daily Log'!$A:$A,">="&$B$3,'Daily Log'!$A:$A,"<="&$B$4) -> 141 | D8: =B8+C8 -> 304 | E8: =IFERROR(_xlfn.XLOOKUP(A8,'RE Rates'!$A:$A,'RE Rates'!$B:$B,0),0) -> 168.3 | I8: =IFERROR(_xlfn.XLOOKUP(A8,'RE Rates'!$A:$A,'RE Rates'!$E:$E,0),0) -> 101.2 | J8: =N(B8)*(N(E8)) -> 27432.9 | K8: =N(C8)*N(I8) -> 14269.2 | L8: =SUMIFS('Daily Log'!$K:$K,'Daily Log'!$B:$B,A8,'Daily Log'!$A:$A,">="&$B$3,'Daily Log'!$A:$A,"<="&$B$4) -> 0 | M8: =SUMIFS('Daily Log'!$G:$G,'Daily Log'!$B:$B,A8,'Daily Log'!$A:$A,">="&$B$3,'Daily Log'!$A:$A,"<="&$B$4) -> 0 | N8: =SUMIFS('Daily Log'!$H:$H,'Daily Log'!$B:$B,A8,'Daily Log'!$A:$A,">="&$B$3,'Daily Log'!$A:$A,"<="&$B$4) -> 0 | O8: =SUMIFS('Daily Log'!$I:$I,'Daily Log'!$B:$B,A8,'Daily Log'!$A:$A,">="&$B$3,'Daily Log'!$A:$A,"<="&$B$4) -> 0 | P8: =SUMIFS('Daily Log'!$J:$J,'Daily Log'!$B:$B,A8,'Daily Log'!$A:$A,">="&$B$3,'Daily Log'!$A:$A,"<="&$B$4) -> 0 | Q8: =SUMIFS('Daily Log'!$L:$L,'Daily Log'!$B:$B,A8,'Daily Log'!$A:$A,">="&$B$3,'Daily Log'!$A:$A,"<="&$B$4) -> 0 | R8: =SUMIFS('Daily Log'!$M:$M,'Daily Log'!$B:$B,A8,'Daily Log'!$A:$A,">="&$B$3,'Daily Log'!$A:$A,"<="&$B$4) -> 0 | S8: =SUMIFS('Daily Log'!$N:$N,'Daily Log'!$B:$B,A8,'Daily Log'!$A:$A,">="&$B$3,'Daily Log'!$A:$A,"<="&$B$4) -> 0 | T8: =N(L8)*IFERROR(_xlfn.XLOOKUP(A8,'RE Rates'!$A:$A,'RE Rates'!$F:$F,0),0)+N(M8)*IFERROR(_xlfn.XLOOKUP(A8,'RE Rates'!$A:$A,'RE Rates'!$G:$G,0),0)+N(N8)*IFERROR(_xlfn.XLOOKUP(A8,'RE Rates'!$A:$A,'RE Rates'!$H:$H,0),0)+N(O8)*IFERROR(_xlfn.XLOOKUP(A8,'RE Rates'!$A:$A,'RE Rates'!$I:$I,0),0)+N(P8)*IFERROR(_xlfn.XLOOKUP(A8,'RE Rates'!$A:$A,'RE Rates'!$J:$J,0),0)+N(Q8)*IFERROR(_xlfn.XLOOKUP(A8,'RE Rates'!$A:$A,'RE Rates'!$K:$K,0),0)+N(R8)*IFERROR(_xlfn.XLOOKUP(A8,'RE Rates'!$A:$A,'RE Rates'!$L:$L,0),0)+N(S8)*IFERROR(_xlfn.XLOOKUP(A8,'RE Rates'!$A:$A,'RE Rates'!$M:$M,0),0) -> 0 | U8: =N(J8)+N(K8)+N(T8) -> 41702.1 | V8: =MAX($L$3 - ROUND(N(D8),2), 0) -> 0 | W8: =N(E8) + N(H8) -> 168.3 | X8: =N(V8) * N(W8) -> 0 | Y8: =N(U8) + N(X8) -> 41702.1
A9: D6 Dozer LGP Tracks | B9: =SUMIFS('Daily Log'!$C:$C,'Daily Log'!$B:$B,A9,'Daily Log'!$A:$A,">="&$B$3,'Daily Log'!$A:$A,"<="&$B$4) -> 104.9 | C9: =SUMIFS('Daily Log'!$D:$D,'Daily Log'!$B:$B,A9,'Daily Log'!$A:$A,">="&$B$3,'Daily Log'!$A:$A,"<="&$B$4) -> 190.1 | D9: =B9+C9 -> 295 | E9: =IFERROR(_xlfn.XLOOKUP(A9,'RE Rates'!$A:$A,'RE Rates'!$B:$B,0),0) -> 255.75 | I9: =IFERROR(_xlfn.XLOOKUP(A9,'RE Rates'!$A:$A,'RE Rates'!$E:$E,0),0) -> 153.45 | J9: =N(B9)*(N(E9)) -> 26828.175 | K9: =N(C9)*N(I9) -> 29170.845 | L9: =SUMIFS('Daily Log'!$K:$K,'Daily Log'!$B:$B,A9,'Daily Log'!$A:$A,">="&$B$3,'Daily Log'!$A:$A,"<="&$B$4) -> 0 | M9: =SUMIFS('Daily Log'!$G:$G,'Daily Log'!$B:$B,A9,'Daily Log'!$A:$A,">="&$B$3,'Daily Log'!$A:$A,"<="&$B$4) -> 0 | N9: =SUMIFS('Daily Log'!$H:$H,'Daily Log'!$B:$B,A9,'Daily Log'!$A:$A,">="&$B$3,'Daily Log'!$A:$A,"<="&$B$4) -> 0 | O9: =SUMIFS('Daily Log'!$I:$I,'Daily Log'!$B:$B,A9,'Daily Log'!$A:$A,">="&$B$3,'Daily Log'!$A:$A,"<="&$B$4) -> 0 | P9: =SUMIFS('Daily Log'!$J:$J,'Daily Log'!$B:$B,A9,'Daily Log'!$A:$A,">="&$B$3,'Daily Log'!$A:$A,"<="&$B$4) -> 0 | Q9: =SUMIFS('Daily Log'!$L:$L,'Daily Log'!$B:$B,A9,'Daily Log'!$A:$A,">="&$B$3,'Daily Log'!$A:$A,"<="&$B$4) -> 0 | R9: =SUMIFS('Daily Log'!$M:$M,'Daily Log'!$B:$B,A9,'Daily Log'!$A:$A,">="&$B$3,'Daily Log'!$A:$A,"<="&$B$4) -> 0 | S9: =SUMIFS('Daily Log'!$N:$N,'Daily Log'!$B:$B,A9,'Daily Log'!$A:$A,">="&$B$3,'Daily Log'!$A:$A,"<="&$B$4) -> 0 | T9: =N(L9)*IFERROR(_xlfn.XLOOKUP(A9,'RE Rates'!$A:$A,'RE Rates'!$F:$F,0),0)+N(M9)*IFERROR(_xlfn.XLOOKUP(A9,'RE Rates'!$A:$A,'RE Rates'!$G:$G,0),0)+N(N9)*IFERROR(_xlfn.XLOOKUP(A9,'RE Rates'!$A:$A,'RE Rates'!$H:$H,0),0)+N(O9)*IFERROR(_xlfn.XLOOKUP(A9,'RE Rates'!$A:$A,'RE Rates'!$I:$I,0),0)+N(P9)*IFERROR(_xlfn.XLOOKUP(A9,'RE Rates'!$A:$A,'RE Rates'!$J:$J,0),0)+N(Q9)*IFERROR(_xlfn.XLOOKUP(A9,'RE Rates'!$A:$A,'RE Rates'!$K:$K,0),0)+N(R9)*IFERROR(_xlfn.XLOOKUP(A9,'RE Rates'!$A:$A,'RE Rates'!$L:$L,0),0)+N(S9)*IFERROR(_xlfn.XLOOKUP(A9,'RE Rates'!$A:$A,'RE Rates'!$M:$M,0),0) -> 0 | U9: =N(J9)+N(K9)+N(T9) -> 55999.02 | V9: =MAX($L$3 - ROUND(N(D9),2), 0) -> 0 | W9: =N(E9) + N(H9) -> 255.75 | X9: =N(V9) * N(W9) -> 0 | Y9: =N(U9) + N(X9) -> 55999.02
A10: Bell 30t Articulated Dumptruck #1 | B10: =SUMIFS('Daily Log'!$C:$C,'Daily Log'!$B:$B,A10,'Daily Log'!$A:$A,">="&$B$3,'Daily Log'!$A:$A,"<="&$B$4) -> 3.3 | C10: =SUMIFS('Daily Log'!$D:$D,'Daily Log'!$B:$B,A10,'Daily Log'!$A:$A,">="&$B$3,'Daily Log'!$A:$A,"<="&$B$4) -> 30 | D10: =B10+C10 -> 33.3 | E10: =IFERROR(_xlfn.XLOOKUP(A10,'RE Rates'!$A:$A,'RE Rates'!$B:$B,0),0) -> 179.3 | I10: =IFERROR(_xlfn.XLOOKUP(A10,'RE Rates'!$A:$A,'RE Rates'!$E:$E,0),0) -> 107.8 | J10: =N(B10)*(N(E10)) -> 591.69 | K10: =N(C10)*N(I10) -> 3234 | L10: =SUMIFS('Daily Log'!$K:$K,'Daily Log'!$B:$B,A10,'Daily Log'!$A:$A,">="&$B$3,'Daily Log'!$A:$A,"<="&$B$4) -> 0 | M10: =SUMIFS('Daily Log'!$G:$G,'Daily Log'!$B:$B,A10,'Daily Log'!$A:$A,">="&$B$3,'Daily Log'!$A:$A,"<="&$B$4) -> 0 | N10: =SUMIFS('Daily Log'!$H:$H,'Daily Log'!$B:$B,A10,'Daily Log'!$A:$A,">="&$B$3,'Daily Log'!$A:$A,"<="&$B$4) -> 0 | O10: =SUMIFS('Daily Log'!$I:$I,'Daily Log'!$B:$B,A10,'Daily Log'!$A:$A,">="&$B$3,'Daily Log'!$A:$A,"<="&$B$4) -> 0 | P10: =SUMIFS('Daily Log'!$J:$J,'Daily Log'!$B:$B,A10,'Daily Log'!$A:$A,">="&$B$3,'Daily Log'!$A:$A,"<="&$B$4) -> 0 | Q10: =SUMIFS('Daily Log'!$L:$L,'Daily Log'!$B:$B,A10,'Daily Log'!$A:$A,">="&$B$3,'Daily Log'!$A:$A,"<="&$B$4) -> 0 | R10: =SUMIFS('Daily Log'!$M:$M,'Daily Log'!$B:$B,A10,'Daily Log'!$A:$A,">="&$B$3,'Daily Log'!$A:$A,"<="&$B$4) -> 0 | S10: =SUMIFS('Daily Log'!$N:$N,'Daily Log'!$B:$B,A10,'Daily Log'!$A:$A,">="&$B$3,'Daily Log'!$A:$A,"<="&$B$4) -> 0 | T10: =N(L10)*IFERROR(_xlfn.XLOOKUP(A10,'RE Rates'!$A:$A,'RE Rates'!$F:$F,0),0)+N(M10)*IFERROR(_xlfn.XLOOKUP(A10,'RE Rates'!$A:$A,'RE Rates'!$G:$G,0),0)+N(N10)*IFERROR(_xlfn.XLOOKUP(A10,'RE Rates'!$A:$A,'RE Rates'!$H:$H,0),0)+N(O10)*IFERROR(_xlfn.XLOOKUP(A10,'RE Rates'!$A:$A,'RE Rates'!$I:$I,0),0)+N(P10)*IFERROR(_xlfn.XLOOKUP(A10,'RE Rates'!$A:$A,'RE Rates'!$J:$J,0),0)+N(Q10)*IFERROR(_xlfn.XLOOKUP(A10,'RE Rates'!$A:$A,'RE Rates'!$K:$K,0),0)+N(R10)*IFERROR(_xlfn.XLOOKUP(A10,'RE Rates'!$A:$A,'RE Rates'!$L:$L,0),0)+N(S10)*IFERROR(_xlfn.XLOOKUP(A10,'RE Rates'!$A:$A,'RE Rates'!$M:$M,0),0) -> 0 | U10: =N(J10)+N(K10)+N(T10) -> 3825.69 | V10: =MAX($L$3 - ROUND(N(D10),2), 0) -> 166.7 | W10: =N(E10) + N(H10) -> 179.3 | X10: =N(V10) * N(W10) -> 29889.31 | Y10: =N(U10) + N(K10) -> 7059.69 | Z10: Is this formula correct?
